<mujoco model="laikago">
    <compiler angle="radian" meshdir="model/laikago" />
    <size njmax="500" nconmax="100" />
    <option gravity="0 0 -9.81"/>
    <asset>
        <mesh name="chassis_vhacd_mod_zup" file="chassis_vhacd_mod_zup.stl" />
        <mesh name="hip_motor_mirror" file="hip_motor_mirror.stl" />
        <mesh name="upper_leg_right_vhacd" file="upper_leg_right_vhacd.stl" />
        <mesh name="lower_leg_3_collision" file="lower_leg_3_collision.stl" />
        <mesh name="hip_motor" file="hip_motor.stl" />
        <mesh name="upper_leg_left_vhacd" file="upper_leg_left_vhacd.stl" />
        <hfield name="terrain" ncol="201" nrow="201" size="30 30 5 .1"/>
    </asset>
    <worldbody>
      <!-- <body pos="-1.448708892931069 1.6172670853172402 0.3718225071063346">
      <freejoint/>
      <geom condim="6" euler="0 0 0" friction="1 0.01 0.01" name="shape_1" pos="0 0 10" rgba="0 0 1 1" size="0.42980092227220745 0.37182250710633463" type="sphere"/>
    </body> -->

    <!--<geom name="floor" type="plane" size="15 15 .5" rgba="1 1 0 1"/>-->

    <!--<site name="target" type="cylinder" size=".4 .06" pos="0 0 .05"/>-->

	<light cutoff="50" diffuse="0.2 .2 .2" dir="-0 0 -1.3" directional="false" exponent="1" pos="0 0 1.3" specular=".5 .5 .5"/>
	<geom conaffinity="1" name="floor" friction="2 0.01 0.01" pos="0 0 -.6" rgba="0.8 0.9 0.8 1" size="40 40 40" type="plane"/>
  <!--<body pos="10 0 1">
  <geom name="sph_geom" contype="1" conaffinity="1" condim="3" type="sphere" mass="1.095" size="0.25" pos="10 0 1" rgba="1 1 1 1"/>
  <freejoint/>
  </body>-->
<body pos="0 0 0">
  <geom type="mesh" contype="1" condim="3" conaffinity="1" group="1" rgba="0 0 1 1" pos="0 0 0" mesh="chassis_vhacd_mod_zup" />
  <!-- <geom type="mesh" rgba="1 1 1 1" mesh="chassis_vhacd_mod_zup" /> -->
  <site name="cog" pos="0 0 0"/>

  <!--<body pos="0 0 10">
        <geom type="mesh" rgba="1 1 1 1" mesh="chassis_vhacd_mod_zup" />
  <freejoint/>
  </body>-->
        <body name="linkQuadFR1" pos="0.199095 -0.0817145 -0.03" quat="0.500003 0.5 0.499997 0.5">
            <inertial pos="0.02 0 0" mass="1.095" diaginertia="0.0001 0.0001 0.0001" />
            <joint name="jointQuadFR1" damping="6" pos="0 0 0" axis="0 0 1" type="hinge" stiffness="2060"/>
            <site name="linkQuadFR1" pos="0 0 0"/>
            <geom type="mesh" contype="0" conaffinity="0" group="1" rgba="1 1 1 1" mesh="hip_motor_mirror" />
            <!-- <geom type="mesh" rgba="1 1 1 1" mesh="hip_motor_mirror" /> -->
            <body name="linkQuadFR2" pos="-0.053565 0 0">
                <inertial pos="0 -0.04 -0.04" mass="1.527" diaginertia="0.0001 0.0001 0.0001" />
                <joint name="jointQuadFR2" damping="6" pos="0 0 0" axis="-1 0 0" type="hinge" stiffness="2060"/>
                <site name="linkQuadFR2" pos="0 0 0"/>
                <geom type="mesh" contype="0" conaffinity="0" group="1" rgba="1 1 1 1" mesh="upper_leg_right_vhacd" />
                <!-- <geom type="mesh" rgba="1 1 1 1" mesh="upper_leg_right_vhacd" /> -->
                <body name="linkQuadFR3" pos="0.02069 -0.20833 -0.1422">
                    <inertial pos="0 -0.186393 -0.0205865" quat="0.494415 0.505524 -0.505524 0.494415" mass="0.341" diaginertia="0.000697746 0.000697746 0.000125" />
                    <joint name="jointQuadFR3" damping="6" pos="0 0 0" axis="-1 0 0" type="hinge" stiffness="2060"/>
                    <site name="linkQuadFR3" pos="0 0 0"/>
                    <geom quat="0.707109 0 0.707105 0" type="mesh" contype="0" conaffinity="0" group="1" rgba="1 1 1 1" mesh="lower_leg_3_collision" />
                    <!-- <geom quat="0.707109 0 0.707105 0" type="mesh" rgba="1 1 1 1" mesh="lower_leg_3_collision" /> -->
                    <geom size="0.0001" pos="0 -0.25 -0.022" contype="0" conaffinity="0" group="1" rgba="1 1 1 1" />
                    <site name="tipQuadFR3" pos="0 -0.25 -0.022"/>
                    <!-- <geom size="0.0001" pos="0 -0.25 -0.022" rgba="1 1 1 1" /> -->
                </body>
            </body>

        </body>
        <body name="linkQuadFL1" pos="0.199095 0.0817145 -0.03" quat="0.500003 0.5 0.499997 0.5">
            <inertial pos="-0.02 0 0" mass="1.095" diaginertia="0.0001 0.0001 0.0001" />
            <joint name="jointQuadFL1" damping="6" pos="0 0 0" axis="0 0 1" type="hinge" stiffness="2060" />
            <site name="linkQuadFL1" pos="0 0 0"/>
            <geom type="mesh" contype="0" conaffinity="0" group="1" rgba="0 0 0 1" mesh="hip_motor" />
            <geom type="mesh" rgba="1 1 1 1" mesh="hip_motor" />
            <body name="linkQuadFL2" pos="0.055855 0 0">
                <inertial pos="0 -0.04 -0.04" mass="1.527" diaginertia="0.0001 0.0001 0.0001" />
                <joint name="jointQuadFL2" damping="6" pos="0 0 0" axis="-1 0 0" type="hinge" stiffness="2060" />
                <site name="linkQuadFL2" pos="0 0 0"/>
                <geom type="mesh" contype="0" conaffinity="0" group="1" rgba="1 1 1 1" mesh="upper_leg_left_vhacd" />
                <!-- <geom type="mesh" rgba="1 1 1 1" mesh="upper_leg_left_vhacd" /> -->
                <body name="linkQuadFL3" pos="-0.02069 -0.20833 -0.1422">
                    <inertial pos="0 -0.186393 -0.0205865" quat="0.494415 0.505524 -0.505524 0.494415" mass="0.341" diaginertia="0.000697746 0.000697746 0.000125" />
                    <joint name="jointQuadFL3" damping="6" pos="0 0 0" axis="-1 0 0" type="hinge" stiffness="2060" />
                    <site name="linkQuadFL3" pos="0 0 0"/>
                    <geom quat="0.707109 0 0.707105 0" type="mesh" contype="0" conaffinity="0" group="1" rgba="1 1 1 1" mesh="lower_leg_3_collision" />
                    <!-- <geom quat="0.707109 0 0.707105 0" type="mesh" rgba="1 1 1 1" mesh="lower_leg_3_collision" /> -->
                    <geom size="0.0001" pos="0 -0.25 -0.022" contype="0" conaffinity="0" group="1" rgba="1 1 1 1" />
                    <site name="tipQuadFL3" pos="0 -0.25 -0.022"/>
                    <!-- <geom size="0.0001" pos="0 -0.25 -0.022" rgba="1 1 1 1" /> -->
                </body>
            </body>
        </body>
        <body name="linkQuadRR1" pos="-0.238195 -0.0817145 -0.03" quat="0.500003 0.5 0.499997 0.5">
            <inertial pos="0.02 0 0" mass="1.095" diaginertia="0.0001 0.0001 0.0001" />
            <joint name="jointQuadRR1" damping="6" pos="0 0 0" axis="0 0 1" type="hinge" stiffness="2060" />
            <site name="linkQuadRR1" pos="0 0 0"/>
            <geom type="mesh" contype="0" conaffinity="0" group="1" rgba="1 1 1 1" mesh="hip_motor_mirror" />
            <geom type="mesh" rgba="1 1 1 1" mesh="hip_motor_mirror" />
            <body name="linkQuadRR2" pos="-0.053565 0 0">
                <inertial pos="0 -0.04 -0.04" mass="1.527" diaginertia="0.0001 0.0001 0.0001" />
                <joint name="jointQuadRR2" damping="1.5" pos="0 0 0" axis="-1 0 0" type="hinge" stiffness="2060" />
                <site name="linkQuadRR2" pos="0 0 0"/>
                <geom type="mesh" contype="0" conaffinity="0" group="1" rgba="1 1 1 1" mesh="upper_leg_right_vhacd" />
                <!-- <geom type="mesh" rgba="1 1 1 1" mesh="upper_leg_right_vhacd" /> -->
                <body name="linkQuadRR3" pos="0.02069 -0.20833 -0.1422">
                    <inertial pos="0 -0.186393 -0.0205865" quat="0.494415 0.505524 -0.505524 0.494415" mass="0.341" diaginertia="0.000697746 0.000697746 0.000125" />
                    <joint name="jointQuadRR3" damping="1.5" pos="0 0 0" axis="-1 0 0" type="hinge" stiffness="2060" />
                    <site name="linkQuadRR3" pos="0 0 0"/>
                    <geom quat="0.707109 0 0.707105 0" type="mesh" contype="0" conaffinity="0" group="1" rgba="1 1 1 1" mesh="lower_leg_3_collision" />
                    <!-- <geom quat="0.707109 0 0.707105 0" type="mesh" rgba="1 1 1 1" mesh="lower_leg_3_collision" /> -->
                    <geom size="0.0001" pos="0 -0.25 -0.022" contype="0" conaffinity="0" group="1" rgba="1 1 1 1" />
                    <site name="tipQuadRR3" pos="0 -0.25 -0.022"/>
                    <!-- <geom size="0.0001" pos="0 -0.25 -0.022" rgba="1 1 1 1" /> -->
                </body>
            </body>
        </body>
        <body name="linkQuadRL1" pos="-0.238195 0.0817145 -0.03" quat="0.500003 0.5 0.499997 0.5">
            <inertial pos="-0.02 0 0" mass="1.095" diaginertia="0.0001 0.0001 0.0001" />
            <joint name="jointQuadRL1" damping="6" pos="0 0 0" axis="0 0 1" type="hinge" stiffness="2060" />
            <site name="linkQuadRL1" pos="0 0 0"/>
            <geom type="mesh" contype="0" conaffinity="0" group="1" rgba="1 1 1 1" mesh="hip_motor" />
            <!-- <geom type="mesh" rgba="1 1 1 1" mesh="hip_motor" /> -->
            <body name="linkQuadRL2" pos="0.055855 0 0">
                <inertial pos="0 -0.04 -0.04" mass="1.527" diaginertia="0.0001 0.0001 0.0001" />
                <joint name="jointQuadRL2" damping="6" pos="0 0 0" axis="-1 0 0" type="hinge" stiffness="2060" />
                <site name="linkQuadRL2" pos="0 0 0"/>
                <geom type="mesh" contype="0" conaffinity="0" group="1" rgba="1 1 1 1" mesh="upper_leg_left_vhacd" />
                <!-- <geom type="mesh" rgba="1 1 1 1" mesh="upper_leg_left_vhacd" /> -->
                <body name="linkQuadRL3" pos="-0.02069 -0.20833 -0.1422">
                    <inertial pos="0 -0.186393 -0.0205865" quat="0.494415 0.505524 -0.505524 0.494415" mass="0.341" diaginertia="0.000597746 0.000597746 2.5e-05" />
                    <joint name="jointQuadRL3" damping="6" pos="0 0 0" axis="-1 0 0" type="hinge" stiffness="2060"/>
                    <site name="linkQuadRL3" pos="0 0 0"/>
                    <geom quat="0.707109 0 0.707105 0" type="mesh" contype="0" conaffinity="0" group="1" rgba="1 1 1 1" mesh="lower_leg_3_collision" />
                    <!-- <geom quat="0.707109 0 0.707105 0" type="mesh" rgba="1 1 1 1" mesh="lower_leg_3_collision" /> -->
                    <geom size="0.0001" pos="0 -0.25 -0.022" contype="0" conaffinity="0" group="1" rgba="1 1 1 1" />
                    <site name="tipQuadRL3" pos="0 -0.25 -0.022"/>
                    <!-- <geom size="0.03" pos="0 -0.25 -0.022" rgba="1 1 1 1" /> -->
                </body>
            </body>
        </body>
<!-- <freejoint name"cgjoint"/> -->
<freejoint />
</body>
</worldbody>
      <actuator>       
        <!--<position name="FR1" kp="5" gear="1.0" ctrllimited="false" forcelimited="false" joint="jointQuadFR1"/>
        <position name="FR2" kp="5" gear="1.0" ctrllimited="false" forcelimited="false" joint="jointQuadFR2"/>
        <position name="FR3" kp="5" gear="1.0" ctrllimited="false" forcelimited="false" joint="jointQuadFR3"/>
        <position name="FL1" kp="5" gear="1.0" ctrllimited="false" forcelimited="false" joint="jointQuadFL1"/>
        <position name="FL2" kp="5" gear="1.0" ctrllimited="false" forcelimited="false" joint="jointQuadFL2"/>
        <position name="FL3" kp="5" gear="1.0" ctrllimited="false" forcelimited="false" joint="jointQuadFL3"/>
        <position name="RR1" kp="5" gear="1.0" ctrllimited="false" forcelimited="false" joint="jointQuadRR1"/>
        <position name="RR2" kp="5" gear="1.0" ctrllimited="false" forcelimited="false" joint="jointQuadRR2"/>
        <position name="RR3" kp="5" gear="1.0" ctrllimited="false" forcelimited="false" joint="jointQuadRR3"/>
        <position name="RL1" kp="5" gear="1.0" ctrllimited="false" forcelimited="false" joint="jointQuadRL1"/>
        <position name="RL2" kp="5" gear="1.0" ctrllimited="false" forcelimited="false" joint="jointQuadRL2"/>
        <position name="RL3" kp="5" gear="1.0" ctrllimited="false" forcelimited="false" joint="jointQuadRL3"/>-->
        <motor name="FR1" gear="6.0" ctrllimited="false" forcelimited="false" joint="jointQuadFR1"/>
        <motor name="FR2" gear="6.0" ctrllimited="false" forcelimited="false" joint="jointQuadFR2"/>
        <motor name="FR3" gear="6.0" ctrllimited="false" forcelimited="false" joint="jointQuadFR3"/>
        <motor name="FL1" gear="6.0" ctrllimited="false" forcelimited="false" joint="jointQuadFL1"/>
        <motor name="FL2" gear="6.0" ctrllimited="false" forcelimited="false" joint="jointQuadFL2"/>
        <motor name="FL3" gear="6.0" ctrllimited="false" forcelimited="false" joint="jointQuadFL3"/>
        <motor name="RR1" gear="6.0" ctrllimited="false" forcelimited="false" joint="jointQuadRR1"/>
        <motor name="RR2" gear="6.0" ctrllimited="false" forcelimited="false" joint="jointQuadRR2"/>
        <motor name="RR3" gear="6.0" ctrllimited="false" forcelimited="false" joint="jointQuadRR3"/>
        <motor name="RL1" gear="6.0" ctrllimited="false" forcelimited="false" joint="jointQuadRL1"/>
        <motor name="RL2" gear="6.0" ctrllimited="false" forcelimited="false" joint="jointQuadRL2"/>
        <motor name="RL3" gear="6.0" ctrllimited="false" forcelimited="false" joint="jointQuadRL3"/>
      </actuator>
      <sensor>
      <jointpos name="FR1angle" joint="jointQuadFR1"/>
      <jointpos name="FR2angle" joint="jointQuadFR2"/>
      <jointpos name="FR3angle" joint="jointQuadFR3"/>
      <jointpos name="FL1angle" joint="jointQuadFL1"/>
      <jointpos name="FL2angle" joint="jointQuadFL2"/>
      <jointpos name="FL3angle" joint="jointQuadFL3"/>
      <jointpos name="RR1angle" joint="jointQuadRR1"/>
      <jointpos name="RR2angle" joint="jointQuadRR2"/>
      <jointpos name="RR3angle" joint="jointQuadRR3"/>
      <jointpos name="RL1angle" joint="jointQuadRL1"/>
      <jointpos name="RL2angle" joint="jointQuadRL2"/>
      <jointpos name="RL3angle" joint="jointQuadRL3"/>
      

      <jointvel name="FR1omeg" joint="jointQuadFR1"/>
      <jointvel name="FR2omeg" joint="jointQuadFR2"/>
      <jointvel name="FR3omeg" joint="jointQuadFR3"/>
      <jointvel name="FL1omeg" joint="jointQuadFL1"/>
      <jointvel name="FL2omeg" joint="jointQuadFL2"/>
      <jointvel name="FL3omeg" joint="jointQuadFL3"/>
      <jointvel name="RR1omeg" joint="jointQuadRR1"/>
      <jointvel name="RR2omeg" joint="jointQuadRR2"/>
      <jointvel name="RR3omeg" joint="jointQuadRR3"/>
      <jointvel name="RL1omeg" joint="jointQuadRL1"/>
      <jointvel name="RL2omeg" joint="jointQuadRL2"/>
      <jointvel name="RL3omeg" joint="jointQuadRL3"/>

      <velocimeter name="cgvel" site="cog"/>
      <accelerometer name="cgacc" site="cog"/>
      <gyro name="cggyro" site="cog"/>

      <torque name="FR1tq" site="linkQuadFR1"/>
      <torque name="FR2tq" site="linkQuadFR2"/>
      <torque name="FR3tq" site="linkQuadFR3"/>
      <torque name="FL1tq" site="linkQuadFL1"/>
      <torque name="FL2tq" site="linkQuadFL2"/>
      <torque name="FL3tq" site="linkQuadFL3"/>
      <torque name="RR1tq" site="linkQuadRR1"/>
      <torque name="RR2tq" site="linkQuadRR2"/>
      <torque name="RR3tq" site="linkQuadRR3"/>
      <torque name="RL1tq" site="linkQuadRL1"/>
      <torque name="RL2tq" site="linkQuadRL2"/>
      <torque name="RL3tq" site="linkQuadRL3"/>

      <touch name="FR3touch" site="tipQuadFR3"/>
      <touch name="FL3touch" site="tipQuadFL3"/>
      <touch name="RR3touch" site="tipQuadRR3"/>
      <touch name="RL3touch" site="tipQuadRL3"/>

      </sensor>
</mujoco>
